<?xml version="1.0"?>
<robot xmlns:xacro="http://www.ros.org/wiki/xacro" xmlns="http://drake.mit.edu">

    <xacro:include filename="inertial_macros.xacro"/>
    <xacro:include filename="visual_macros.xacro"/>

    <xacro:property name="shoulder_radius" value="${.18/2}" />
    <xacro:property name="shoulder_height" value=".1615" />

    <xacro:property name="upperarm_length" value=".30381" />
    <xacro:property name="upperarm_height" value="0.070471" />
    <xacro:property name="upperarm_mass" value="0.4" />

    <xacro:property name="forearm_length" value=".259916" />
    <xacro:property name="forearm_height" value=".02545" />
    <xacro:property name="forearm_mass" value="0.3" />

    <xacro:property name="end_effector_radius" value="${.1/2}" />
    <xacro:property name="end_effector_length" value="0.1" />
    <xacro:property name="end_effector_height" value="0.02" />
    <xacro:property name="end_effector_mass" value=".1" />

    <link name="base_link"></link>    
    
    <joint name="odrive_joint" type="fixed">
        <parent link="base_link"/>
        <child link="odrive_base"/>
    </joint>

    <link name="odrive_base">
        <xacro:cylinder_identical_collision mass="3" radius="${shoulder_radius}" height="${shoulder_height}">
            <material name="blue">
                <color rgba="0 0 1 1" />
            </material>
        </xacro:cylinder_identical_collision>
    </link>

    <joint name="shoulder" type="revolute">
        <parent link="odrive_base"/>
        <child link="upperarm"/>
        <origin xyz="0 0 ${shoulder_height}"/>
        <axis xyz="0 0 1" />
        <limit upper="${pi/2}" lower="-${pi/2}" effort=".1" velocity=".5"/>
        <!-- <limit drake:acceleration="8.57" effort="320" lower="-2.96705972839" upper="2.96705972839" velocity="1.4835298641951802"/>
        <dynamics damping="0.5"/> -->
    </joint>

    <link name="upperarm">
        <xacro:square_prism_identical_collision mass="${upperarm_mass}" length="${upperarm_length}" height="${upperarm_height}">
            <material name="green">
                <color rgba="0 1 0 1" />
            </material>
        </xacro:square_prism_identical_collision>
        <xacro:square_prism_inertial mass="${upperarm_mass}" length="${upperarm_length}" height="${upperarm_height}"/>
    </link>

    <joint name="elbow" type="revolute">
        <parent link="upperarm"/>
        <child link="forearm"/>
        <!-- start at pi/2 so not at a singularity -->
        <origin xyz="0 ${upperarm_length} ${upperarm_height}" rpy="0 0 ${pi/2}"/>
        <axis xyz="0 0 1" />
        <limit upper="${pi/2}" lower="-${pi/2}" effort=".1" velocity=".5"/>
        <!-- <limit drake:acceleration="8.57" effort="320" lower="-2.96705972839" upper="2.96705972839" velocity="1.4835298641951802"/>
        <dynamics damping="0.5"/> -->
    </joint>

    <link name="forearm">
        <xacro:square_prism_identical_collision mass="${forearm_mass}" length="${forearm_length}" height="${forearm_height}">
            <material name="red">
                <color rgba="1 0 0 1" />
            </material>
        </xacro:square_prism_identical_collision>
        <xacro:square_prism_inertial mass="${forearm_mass}" length="${forearm_length}" height="${forearm_height}"/>
    </link>

    <joint name="wrist" type="fixed">
        <parent link="forearm"/>
        <child link="end_effector"/>
        <origin xyz="0 ${forearm_length} ${forearm_height}" rpy="-${pi/2} 0 0"/>
        <axis xyz="0 0 1" />
        <limit upper="${pi/2}" lower="-${pi/2}" effort=".1" velocity=".5"/>
        <!-- <limit drake:acceleration="8.57" effort="320" lower="-2.96705972839" upper="2.96705972839" velocity="1.4835298641951802"/>
        <dynamics damping="0.5"/> -->
    </joint>

    <link name="end_effector">
        <xacro:square_prism_identical_collision mass="${end_effector_mass}" length="${end_effector_length}" height="${end_effector_height}">
            <material name="orange">
                <color rgba="1 0 1 1" />
            </material>
        </xacro:square_prism_identical_collision>
        <xacro:square_prism_inertial mass="${end_effector_mass}" length="${end_effector_length}" height="${end_effector_height}"/>
    </link>

    <!-- Drake 'MultibodyPlant does not currently support non-default mechanical reductions.' -->
    <!-- <transmission name="transm" type="SimpleTransmission">
        <joint name="shoulder"/>
        <actuator name="shoulder_motor"/>
        <mechanicalReduction>.1</mechanicalReduction>
    </transmission> -->


</robot>